<?xml version="1.0" ?><!-- =================================================================================== --><!-- |    This document was autogenerated by xacro from /home/lbarnett/ros2_ws/install/rcraicer_description/share/rcraicer_description/urdf/rcraicer.urdf.xacro | --><!-- |    EDITING THIS FILE BY HAND IS NOT RECOMMENDED                                 | --><!-- =================================================================================== --><!-- augmented_rc_car.urdf.xacro
This file defines a model of a RC Car augmented with sensors
It is based on the Traxxas(R) E-Maxx(R) #3905 RC (Radio Controlled)
truck model: 
Here below are the description given for the em_3905 model:
Lengths are measured in meters, angles are measured in radians, and masses are
measured in kilograms. All of these values are approximations.
To work with Gazebo, each link must have an inertial element, even if
the link only serves to connect two joints. To be visible in Gazebo, a link
must have a collision element. Furthermore, the link must have a Gazebo
material.
Traxxas(R), E-Maxx(R), and Titan(R) are registered trademarks of Traxxas
Management, LLC. em_3905.urdf.xacro was independently created by Wunderkammer
Laboratory, and neither em_3905.urdf.xacro nor Wunderkammer Laboratory is
affiliated with, sponsored by, approved by, or endorsed by Traxxas Management,
LLC. Mabuchi Motor(R) is a registered trademark of Mabuchi Motor Co., Ltd.
Corporation Japan. All other trademarks and service marks are the property of
their respective owners.
Copyright (c) 2011-2013 Wunderkammer Laboratory
Licensed under the Apache License, Version 2.0 (the "License");
you may not use this file except in compliance with the License.
You may obtain a copy of the License at
  http://www.apache.org/licenses/LICENSE-2.0
Unless required by applicable law or agreed to in writing, software
distributed under the License is distributed on an "AS IS" BASIS,
WITHOUT WARRANTIES OR CONDITIONS OF ANY KIND, either express or implied.
See the License for the specific language governing permissions and
limitations under the License.
--><robot name="rcraicer"><material name="battery_mat"><color rgba="0 0 1 1"/></material><material name="chassis_mat"><color rgba="0.5 0.5 0.5 1"/></material><material name="tire_mat"><color rgba="0 0 0 1"/></material><!-- base_link must have geometry so that its axes can be displayed in
       rviz. --><link name="base_link"><visual><geometry><box size="0.05 0.05 0.01"/></geometry><material name="chassis_mat"/></visual></link><gazebo reference="base_link"><material>Gazebo/Green</material></gazebo><link name="bumper_link"><visual><geometry><box size="0.01 0.3 0.01"/></geometry></visual><collision><!-- origin is relative --><geometry><box size="0.01 0.3 0.01"/></geometry></collision></link><gazebo reference="bumper_link"><material>Gazebo/Black</material></gazebo><joint name="baselink_to_bumper" type="fixed"><parent link="base_link"/><child link="bumper_link"/><origin rpy="0.0 0.0 0.0" xyz="0.295 0.0 0.0"/></joint><link name="eye_link"><visual><geometry><box size="0.05 0.1 0.03"/></geometry></visual><collision><!-- origin is relative --><geometry><box size="0.05 0.1 0.03"/></geometry></collision></link><gazebo reference="eye_link"><material>Gazebo/Red</material></gazebo><link name="left_eye"><visual><geometry><sphere radius="0.01"/></geometry></visual></link><gazebo reference="left_eye"><material>Gazebo/Green</material></gazebo><link name="right_eye"><visual><geometry><sphere radius="0.01"/></geometry></visual></link><gazebo reference="right_eye"><material>Gazebo/Green</material></gazebo><joint name="left_eye_to_head" type="fixed"><parent link="eye_link"/><child link="left_eye"/><origin rpy="0.0 0.0 0.0" xyz="0.03 0.03 0.0"/></joint><joint name="right_eye_to_head" type="fixed"><parent link="eye_link"/><child link="right_eye"/><origin rpy="0.0 0.0 0.0" xyz="0.03 -0.03 0.0"/></joint><joint name="base_link_to_eye" type="fixed"><parent link="base_link"/><child link="eye_link"/><origin rpy="0.0 0.0 0.0" xyz="0.205 0.0 0.1"/></joint><joint name="imu_joint" type="fixed"><axis xyz="1 0 0"/><origin xyz="0 0 0.19"/><parent link="base_link"/><child link="imu_link"/></joint><link name="imu_link"><inertial><mass value="0.001"/><origin rpy="0 0 0" xyz="0 0 0"/><inertia ixx="0.0001" ixy="0" ixz="0" iyy="0.000001" iyz="0" izz="0.0001"/></inertial><visual><origin rpy="0 0 0" xyz="0 0 0"/><geometry><box size="0.001 0.001 0.001"/></geometry></visual><collision><origin rpy="0 0 0" xyz="0 0 0"/><geometry><box size=".001 .001 .001"/></geometry></collision></link><!-- Chassis --><link name="chassis"><visual><origin xyz="0 0 -0.005"/><geometry><box size="0.35 0.168 0.01"/></geometry><material name="chassis_mat"/></visual><collision><origin xyz="0 0 -0.005"/><geometry><box size="0.35 0.168 0.01"/></geometry></collision><inertial><origin xyz="0 0 -0.005"/><mass value="2.788"/><inertia ixx="0.0065806093333333334" ixy="0" ixz="0" iyy="0.028484066666666658" iyz="0" izz="0.035018209333333335"/></inertial></link><gazebo reference="chassis"><material>Gazebo/Grey</material></gazebo><joint name="base_link_to_chasis" type="fixed"><parent link="base_link"/><child link="chassis"/></joint><joint name="chassis_to_left_battery" type="fixed"><parent link="chassis"/><child link="left_battery_offset"/><origin rpy="0.34906585 0 0" xyz="-0.025                    0.0325                    0"/></joint><link name="left_battery_offset"><inertial><mass value="0.001"/><inertia ixx="0.001" ixy="0" ixz="0" iyy="0.001" iyz="0" izz="0.001"/></inertial></link><joint name="offset_to_left_battery" type="fixed"><parent link="left_battery_offset"/><child link="left_battery"/><origin xyz="0                    0.0235                    -0.008"/></joint><link name="left_battery"><visual><geometry><box size="0.16 0.047 0.024"/></geometry><material name="battery_mat"/></visual><collision><geometry><box size="0.16 0.047 0.024"/></geometry></collision><inertial><origin/><mass value="0.5025"/><inertia ixx="0.000116621875" ixy="0" ixz="0" iyy="0.00109612" iyz="0" izz="0.0011645018749999998"/></inertial></link><gazebo reference="left_battery"><material>Gazebo/Blue</material></gazebo><joint name="chassis_to_right_battery" type="fixed"><parent link="chassis"/><child link="right_battery_offset"/><origin rpy="-0.34906585 0 0" xyz="-0.025                    -0.0325                    0"/></joint><link name="right_battery_offset"><inertial><mass value="0.001"/><inertia ixx="0.001" ixy="0" ixz="0" iyy="0.001" iyz="0" izz="0.001"/></inertial></link><joint name="offset_to_right_battery" type="fixed"><parent link="right_battery_offset"/><child link="right_battery"/><origin xyz="0                    -0.0235                    -0.008"/></joint><link name="right_battery"><visual><geometry><box size="0.16 0.047 0.024"/></geometry><material name="battery_mat"/></visual><collision><geometry><box size="0.16 0.047 0.024"/></geometry></collision><inertial><origin/><mass value="0.5025"/><inertia ixx="0.000116621875" ixy="0" ixz="0" iyy="0.00109612" iyz="0" izz="0.0011645018749999998"/></inertial></link><gazebo reference="right_battery"><material>Gazebo/Blue</material></gazebo><joint name="left_front_shock" type="prismatic"><parent link="chassis"/><child link="left_steering_link"/><origin xyz="0.1675                    0.1525                    -0.0235"/><axis xyz="0 0 -1"/><limit effort="12.5106" lower="-0.042" upper="0.042" velocity="1000"/></joint><transmission name="left_front_shock_trans"><type>transmission_interface/SimpleTransmission</type><joint name="left_front_shock"/><actuator name="left_front_shock_act"><hardwareInterface>EffortJointInterface</hardwareInterface><mechanicalReduction>1</mechanicalReduction></actuator></transmission><link name="left_steering_link"><inertial><mass value="0.001"/><inertia ixx="0.001" ixy="0" ixz="0" iyy="0.001" iyz="0" izz="0.001"/></inertial></link><joint name="left_steering_joint" type="revolute"><parent link="left_steering_link"/><child link="left_front_axle_carrier"/><axis xyz="0 0 1"/><limit effort="0.5649" lower="-0.785398163" upper="0.785398163" velocity="4.553"/></joint><transmission name="left_steering_trans"><type>transmission_interface/SimpleTransmission</type><joint name="left_steering_joint"/><actuator name="left_steering_act"><hardwareInterface>EffortJointInterface</hardwareInterface><mechanicalReduction>1</mechanicalReduction></actuator></transmission><link name="left_front_axle_carrier"><inertial><mass value="0.001"/><inertia ixx="0.001" ixy="0" ixz="0" iyy="0.001" iyz="0" izz="0.001"/></inertial></link><!-- The left and right axles have the same axis so that identical
         rotation values cause the wheels to rotate in the same direction. --><joint name="left_front_axle" type="continuous"><parent link="left_front_axle_carrier"/><child link="left_front_wheel"/><origin rpy="1.57079633 0 0"/><axis xyz="0 0 -1"/><limit effort="5.12766" velocity="244.8696"/></joint><transmission name="left_front_axle_trans"><type>transmission_interface/SimpleTransmission</type><joint name="left_front_axle"/><actuator name="left_front_axle_act"><hardwareInterface>EffortJointInterface</hardwareInterface><mechanicalReduction>1</mechanicalReduction></actuator></transmission><link name="left_front_wheel"><visual><origin xyz="0                      -6.938893903907228e-18                      0"/><geometry><cylinder length="0.0889" radius="0.073025"/></geometry><material name="tire_mat"/></visual><collision><origin xyz="0                      -6.938893903907228e-18                      0"/><geometry><cylinder length="0.0889" radius="0.073025"/></geometry></collision><inertial><mass value="0.29"/><inertia ixx="0.0007464659129791666" ixy="0" ixz="0" iyy="0.0007464659129791666" iyz="0" izz="0.001110943342625"/></inertial></link><gazebo reference="left_front_wheel"><material>Gazebo/Black</material></gazebo><joint name="right_front_shock" type="prismatic"><parent link="chassis"/><child link="right_steering_link"/><origin xyz="0.1675                    -0.1525                    -0.0235"/><axis xyz="0 0 -1"/><limit effort="12.5106" lower="-0.042" upper="0.042" velocity="1000"/></joint><transmission name="right_front_shock_trans"><type>transmission_interface/SimpleTransmission</type><joint name="right_front_shock"/><actuator name="right_front_shock_act"><hardwareInterface>EffortJointInterface</hardwareInterface><mechanicalReduction>1</mechanicalReduction></actuator></transmission><link name="right_steering_link"><inertial><mass value="0.001"/><inertia ixx="0.001" ixy="0" ixz="0" iyy="0.001" iyz="0" izz="0.001"/></inertial></link><joint name="right_steering_joint" type="revolute"><parent link="right_steering_link"/><child link="right_front_axle_carrier"/><axis xyz="0 0 1"/><limit effort="0.5649" lower="-0.785398163" upper="0.785398163" velocity="4.553"/></joint><transmission name="right_steering_trans"><type>transmission_interface/SimpleTransmission</type><joint name="right_steering_joint"/><actuator name="right_steering_act"><hardwareInterface>EffortJointInterface</hardwareInterface><mechanicalReduction>1</mechanicalReduction></actuator></transmission><link name="right_front_axle_carrier"><inertial><mass value="0.001"/><inertia ixx="0.001" ixy="0" ixz="0" iyy="0.001" iyz="0" izz="0.001"/></inertial></link><!-- The left and right axles have the same axis so that identical
         rotation values cause the wheels to rotate in the same direction. --><joint name="right_front_axle" type="continuous"><parent link="right_front_axle_carrier"/><child link="right_front_wheel"/><origin rpy="1.57079633 0 0"/><axis xyz="0 0 -1"/><limit effort="5.12766" velocity="244.8696"/></joint><transmission name="right_front_axle_trans"><type>transmission_interface/SimpleTransmission</type><joint name="right_front_axle"/><actuator name="right_front_axle_act"><hardwareInterface>EffortJointInterface</hardwareInterface><mechanicalReduction>1</mechanicalReduction></actuator></transmission><link name="right_front_wheel"><visual><origin xyz="0                      6.938893903907228e-18                      0"/><geometry><cylinder length="0.0889" radius="0.073025"/></geometry><material name="tire_mat"/></visual><collision><origin xyz="0                      6.938893903907228e-18                      0"/><geometry><cylinder length="0.0889" radius="0.073025"/></geometry></collision><inertial><mass value="0.29"/><inertia ixx="0.0007464659129791666" ixy="0" ixz="0" iyy="0.0007464659129791666" iyz="0" izz="0.001110943342625"/></inertial></link><gazebo reference="right_front_wheel"><material>Gazebo/Black</material></gazebo><joint name="left_rear_shock" type="prismatic"><parent link="chassis"/><child link="left_rear_axle_carrier"/><origin xyz="-0.1675                    0.1525                    -0.0235"/><axis xyz="0 0 -1"/><limit effort="12.5106" lower="-0.042" upper="0.042" velocity="1000"/></joint><transmission name="left_rear_shock_trans"><type>transmission_interface/SimpleTransmission</type><joint name="left_rear_shock"/><actuator name="left_rear_shock_act"><hardwareInterface>EffortJointInterface</hardwareInterface><mechanicalReduction>1</mechanicalReduction></actuator></transmission><link name="left_rear_axle_carrier"><inertial><mass value="0.001"/><inertia ixx="0.001" ixy="0" ixz="0" iyy="0.001" iyz="0" izz="0.001"/></inertial></link><!-- The left and right axles have the same axis so that identical
         rotation values cause the wheels to rotate in the same direction. --><joint name="left_rear_axle" type="continuous"><parent link="left_rear_axle_carrier"/><child link="left_rear_wheel"/><origin rpy="1.57079633 0 0"/><axis xyz="0 0 -1"/><limit effort="5.12766" velocity="244.8696"/></joint><transmission name="left_rear_axle_trans"><type>transmission_interface/SimpleTransmission</type><joint name="left_rear_axle"/><actuator name="left_rear_axle_act"><hardwareInterface>EffortJointInterface</hardwareInterface><mechanicalReduction>1</mechanicalReduction></actuator></transmission><link name="left_rear_wheel"><visual><origin xyz="0                      -6.938893903907228e-18                      0"/><geometry><cylinder length="0.0889" radius="0.073025"/></geometry><material name="tire_mat"/></visual><collision><origin xyz="0                      -6.938893903907228e-18                      0"/><geometry><cylinder length="0.0889" radius="0.073025"/></geometry></collision><inertial><mass value="0.29"/><inertia ixx="0.0007464659129791666" ixy="0" ixz="0" iyy="0.0007464659129791666" iyz="0" izz="0.001110943342625"/></inertial></link><gazebo reference="left_rear_wheel"><material>Gazebo/Black</material></gazebo><joint name="right_rear_shock" type="prismatic"><parent link="chassis"/><child link="right_rear_axle_carrier"/><origin xyz="-0.1675                    -0.1525                    -0.0235"/><axis xyz="0 0 -1"/><limit effort="12.5106" lower="-0.042" upper="0.042" velocity="1000"/></joint><transmission name="right_rear_shock_trans"><type>transmission_interface/SimpleTransmission</type><joint name="right_rear_shock"/><actuator name="right_rear_shock_act"><hardwareInterface>EffortJointInterface</hardwareInterface><mechanicalReduction>1</mechanicalReduction></actuator></transmission><link name="right_rear_axle_carrier"><inertial><mass value="0.001"/><inertia ixx="0.001" ixy="0" ixz="0" iyy="0.001" iyz="0" izz="0.001"/></inertial></link><!-- The left and right axles have the same axis so that identical
         rotation values cause the wheels to rotate in the same direction. --><joint name="right_rear_axle" type="continuous"><parent link="right_rear_axle_carrier"/><child link="right_rear_wheel"/><origin rpy="1.57079633 0 0"/><axis xyz="0 0 -1"/><limit effort="5.12766" velocity="244.8696"/></joint><transmission name="right_rear_axle_trans"><type>transmission_interface/SimpleTransmission</type><joint name="right_rear_axle"/><actuator name="right_rear_axle_act"><hardwareInterface>EffortJointInterface</hardwareInterface><mechanicalReduction>1</mechanicalReduction></actuator></transmission><link name="right_rear_wheel"><visual><origin xyz="0                      6.938893903907228e-18                      0"/><geometry><cylinder length="0.0889" radius="0.073025"/></geometry><material name="tire_mat"/></visual><collision><origin xyz="0                      6.938893903907228e-18                      0"/><geometry><cylinder length="0.0889" radius="0.073025"/></geometry></collision><inertial><mass value="0.29"/><inertia ixx="0.0007464659129791666" ixy="0" ixz="0" iyy="0.0007464659129791666" iyz="0" izz="0.001110943342625"/></inertial></link><gazebo reference="right_rear_wheel"><material>Gazebo/Black</material></gazebo></robot>